Workbook

Sheet Sprint 1
A1: Project name: | C1: Xây dựng website đặt tour du lịch tích hợp hệ thống gợi ý dựa trên AI | F1: Kết thúc đúng hạn
A2: Module name: | C2: Sprint 1 | F2: Muộn
A3: Start date: | C3: 46103 | F3: Trước thời hạn
A4: End date: | C4: 46126 | F4: Kết thúc đúng hạn
B6: SPRINT 1 REPORT
B7: No | C7: Thành viên | D7: Thực tế | E7: Ước tính
B8: 1 | C8: Phạm Văn Bảo | D8: =SUMIF($E$16:$F$84,"Bảo",$G$16:$G$84)+SUMIF($E$16:$F$84,"All team",$G$16:$G$84)/5+SUMIF($E$16:$F$84,"Bảo,Quân",$G$16:$G$84)/2+SUMIF($E$16:$F$84,"Bảo,Trung",$G$16:$G$84)/2 -> 37.5 | E8: =SUMIF($E$16:$F$84,"Bảo",$H$16:$H$84)+SUMIF($E$16:$F$84,"All team",$H$16:$H$84)/5+SUMIF($E$16:$F$84,"Bảo,Quân",$H$16:$H$84)/2+SUMIF($E$16:$F$84,"Bảo,Trung",$H$16:$H$84)/2 -> 41.2
B9: 2 | C9: Phạm Minh Quân | D9: =SUMIF($E$16:$F$84,"Quân",$G$16:$G$84)+SUMIF($E$16:$F$84,"All team",$G$16:$G$84)/5+SUMIF($E$16:$F$84,"Bảo,Quân",$G$16:$G$84)/2+SUMIF($E$16:$F$84,"Quân,Trung",$G$16:$G$84)/2 -> 30.5 | E9: =SUMIF($E$16:$F$84,"Quân",$H$16:$H$84)+SUMIF($E$16:$F$84,"All team",$H$16:$H$84)/5+SUMIF($E$16:$F$84,"Bảo,Quân",$H$16:$H$84)/2+SUMIF($E$16:$F$84,"Quân,Trung",$H$16:$H$84)/2 -> 30.2
B10: 3 | C10: Võ Hồ Thành Trung | D10: =SUMIF($E$16:$F$84,"Trung",$G$16:$G$84)+SUMIF($E$16:$F$84,"All team",$G$16:$G$84)/5+SUMIF($E$16:$F$84,"Bảo,Trung",$G$16:$G$84)/2+SUMIF($E$16:$F$84,"Quân,Trung",$G$16:$G$84)/2 -> 34.5 | E10: =SUMIF($E$16:$F$84,"Trung",$H$16:$H$84)+SUMIF($E$16:$F$84,"All team",$H$16:$H$84)/5+SUMIF($E$16:$F$84,"Bảo,Trung",$H$16:$H$84)/2+SUMIF($E$16:$F$84,"Quân,Trung",$H$16:$H$84)/2 -> 36.2
B11: 4 | C11: Lê Thanh Hà | D11: =SUMIF($E$16:$F$84,"Hà",$G$16:$G$84)+SUMIF($E$16:$F$84,"All team",$G$16:$G$84)/5+SUMIF($E$16:$F$84,"Hà,Luân",$G$16:$G$84)/2 -> 33.5 | E11: =SUMIF($E$16:$F$84,"Hà",$H$16:$H$84)+SUMIF($E$16:$F$84,"All team",$H$16:$H$84)/5+SUMIF($E$16:$F$84,"Hà,Luân",$H$16:$H$84)/2 -> 37.2
B12: 5 | C12: Nguyễn Thành Luân | D12: =SUMIF($E$16:$F$84,"Luân",$G$16:$G$84)+SUMIF($E$16:$F$84,"All team",$G$16:$G$84)/5+SUMIF($E$16:$F$84,"Hà,Luân",$G$16:$G$84)/2 -> 28 | E12: =SUMIF($E$16:$F$84,"Luân",$H$16:$H$84)+SUMIF($E$16:$F$84,"All team",$H$16:$H$84)/5+SUMIF($E$16:$F$84,"Hà,Luân",$H$16:$H$84)/2 -> 28.2
B13: Tổng | D13: =SUM(D8:D12) -> 164 | E13: =SUM(E8:E12) -> 173
A15: Sprint | B15: Compoment | C15: Task name | E15: Responsible Member | G15: Thực tế | H15: Ước tính | I15: 46100 | J15: 46101 | K15: 46102 | L15: 46103 | M15: 46104 | N15: 46105 | O15: 46106 | P15: 46107 | Q15: 46108 | R15: 46109 | S15: 46110 | T15: 46111 | U15: 46112 | V15: 46113 | W15: 46114
A16: Sprint 1 | B16: Họp kế hoạch Sprint | E16: All team | G16: 8 | H16: 8 | I16: 0 | J16: 0 | K16: 0 | L16: 0 | M16: 0 | N16: 0 | O16: 0 | P16: 0 | Q16: 0 | R16: 0 | S16: 0 | T16: 0 | U16: 0 | V16: 0 | W16: 0
B17: Tạo Sprint Backlog 1 | E17: Bảo,Trung | G17: 12 | H17: 12 | I17: 12 | J17: 0 | K17: 0 | L17: 0 | M17: 0 | N17: 0 | O17: 0 | P17: 0 | Q17: 0 | R17: 0 | S17: 0 | T17: 0 | U17: 0 | V17: 0 | W17: 0
B18: Tạo tài liệu kiểm thử cho Sprint | E18: Hà,Luân | G18: 10 | H18: 10 | I18: 10 | J18: 0 | K18: 0 | L18: 0 | M18: 0 | N18: 0 | O18: 0 | P18: 0 | Q18: 0 | R18: 0 | S18: 0 | T18: 0 | U18: 0 | V18: 0 | W18: 0
B19: User interface design | C19: Giao diện đăng ký | E19: Trung | G19: 0.5 | H19: 1 | I19: 1 | J19: 0.5 | K19: 0 | L19: 0 | M19: 0 | N19: 0 | O19: 0 | P19: 0 | Q19: 0 | R19: 0 | S19: 0 | T19: 0 | U19: 0 | V19: 0 | W19: 0
K20: 0.5
C21: Giao diện đăng nhập | E21: Trung | G21: 1 | H21: 1 | I21: 1 | J21: 1 | K21: 0 | L21: 0 | M21: 0 | N21: 0 | O21: 0 | P21: 0 | Q21: 0 | R21: 0 | S21: 0 | T21: 0 | U21: 0 | V21: 0 | W21: 0
C22: Giao diện đăng xuất | E22: Luân | G22: 1 | H22: 1 | I22: 1 | J22: 1 | K22: 0 | L22: 0 | N22: 0 | O22: 0 | P22: 0 | Q22: 0 | R22: 0 | S22: 0 | T22: 0 | U22: 0 | V22: 0 | W22: 0
C23: Giao diện quên mật khẩu | E23: Luân | G23: 1 | H23: 1 | I23: 1 | J23: 1 | K23: 0 | L23: 0 | M23: 0 | N23: 0 | O23: 0 | P23: 0 | Q23: 0 | R23: 0 | S23: 0 | T23: 0 | U23: 0 | V23: 0 | W23: 0
C24: Giao diện xem thông tin tour | E24: Quân | G24: 1 | H24: 1 | I24: 1 | J24: 1 | K24: 0 | L24: 0 | M24: 0 | N24: 0 | O24: 0 | P24: 0 | Q24: 0 | R24: 0 | S24: 0 | T24: 0 | U24: 0 | V24: 0 | W24: 0
C25: Giao diện đặt tour | E25: Hà | G25: 1 | H25: 2 | I25: 2 | J25: 1 | K25: 0 | L25: 0 | M25: 0 | N25: 0 | O25: 0 | P25: 0 | Q25: 0 | R25: 0 | S25: 0 | T25: 0 | U25: 0 | V25: 0 | W25: 0
K26: 1
C27: Giao diện thanh toán | E27: Quân | G27: 2 | H27: 2 | I27: 2 | J27: 2 | K27: 0 | L27: 0 | M27: 0 | N27: 0 | O27: 0 | P27: 0 | Q27: 0 | R27: 0 | S27: 0 | T27: 0 | U27: 0 | V27: 0 | W27: 0
C28: Review all user interfaces of sprint 1 | E28: All team | G28: 2 | H28: 4 | I28: 4 | J28: 2 | K28: 0 | L28: 0 | M28: 0 | N28: 0 | O28: 0 | P28: 0 | Q28: 0 | R28: 0 | S28: 0 | T28: 0 | U28: 0 | V28: 0 | W28: 0
K29: 2
B30: Design test case | C30: Thiêt kế trường kiểm thử cho đăng ký | E30: Luân | G30: 1.5 | H30: 1 | I30: 1 | J30: 1 | K30: 1 | L30: 0 | M30: 0 | N30: 0 | O30: 0 | P30: 0 | Q30: 0 | R30: 0 | S30: 0 | T30: 0 | U30: 0 | V30: 0 | W30: 0
L31: 0.5
C32: Thiêt kế trường kiểm thử cho đăng nhập | E32: Hà | G32: 1 | H32: 1 | I32: 1 | J32: 1 | K32: 1 | L32: 0 | M32: 0 | N32: 0 | O32: 0 | P32: 0 | Q32: 0 | R32: 0 | S32: 0 | T32: 0 | U32: 0 | V32: 0 | W32: 0
C33: Thiêt kế trường kiểm thử cho đăng xuất | E33: Quân | G33: 1 | H33: 1 | I33: 1 | J33: 1 | K33: 1 | L33: 0 | M33: 0 | N33: 0 | O33: 0 | P33: 0 | Q33: 0 | R33: 0 | S33: 0 | T33: 0 | U33: 0 | V33: 0 | W33: 0
C34: Thiêt kế trường kiểm thử cho quên mật khẩu | E34: Bảo | G34: 2 | H34: 2 | I34: 2 | J34: 2 | K34: 2 | L34: 0 | M34: 0 | N34: 0 | O34: 0 | P34: 0 | Q34: 0 | R34: 0 | S34: 0 | T34: 0 | U34: 0 | V34: 0 | W34: 0
C35: Thiêt kế trường kiểm thử cho xem thông tin tour | E35: Trung | G35: 2 | H35: 2 | I35: 2 | J35: 2 | K35: 2 | L35: 0 | M35: 0 | N35: 0 | O35: 0 | P35: 0 | Q35: 0 | R35: 0 | S35: 0 | T35: 0 | U35: 0 | V35: 0 | W35: 0
C36: Thiêt kế trường kiểm thử cho đặt tour | E36: Hà | G36: 2 | H36: 2 | I36: 2 | J36: 2 | K36: 2 | L36: 0 | M36: 0 | N36: 0 | O36: 0 | P36: 0 | Q36: 0 | R36: 0 | S36: 0 | T36: 0 | U36: 0 | V36: 0 | W36: 0
C37: Thiêt kế trường kiểm thử cho thanh toán | E37: Luân | G37: 1 | H37: 1 | I37: 1 | J37: 1 | K37: 1 | L37: 0 | M37: 0 | N37: 0 | O37: 0 | P37: 0 | Q37: 0 | R37: 0 | S37: 0 | T37: 0 | U37: 0 | V37: 0 | W37: 0
C38: Review all test case of Sprint 1 | E38: All team | G38: 5 | H38: 5 | I38: 5 | J38: 5 | K38: 5 | L38: 0 | M38: 0 | N38: 0 | O38: 0 | P38: 0 | Q38: 0 | R38: 0 | S38: 0 | T38: 0 | U38: 0 | V38: 0 | W38: 0
B39: Coding | C39: Code back-end cho đăng ký | E39: Bảo | G39: 5 | H39: 5 | I39: 5 | J39: 5 | K39: 5 | L39: 5 | M39: 0 | N39: 0 | O39: 0 | P39: 0 | Q39: 0 | R39: 0 | S39: 0 | T39: 0 | U39: 0 | V39: 0 | W39: 0
C40: Thiết kê front-end cho đằng ký | E40: Trung | G40: 2 | H40: 2 | I40: 2 | J40: 2 | K40: 2 | L40: 2 | M40: 0 | N40: 0 | O40: 0 | P40: 0 | Q40: 0 | R40: 0 | S40: 0 | T40: 0 | U40: 0 | V40: 0 | W40: 0
C41: Code back-end cho đăng nhập | E41: Bảo | G41: 5 | H41: 5 | I41: 5 | J41: 5 | K41: 5 | L41: 5 | M41: 0 | N41: 0 | O41: 0 | P41: 0 | Q41: 0 | R41: 0 | S41: 0 | T41: 0 | U41: 0 | V41: 0 | W41: 0
C42: Thiết kê front-end cho đăng nhập | E42: Quân | G42: 2 | H42: 2 | I42: 2 | J42: 2 | K42: 2 | L42: 2 | M42: 0 | N42: 0 | O42: 0 | P42: 0 | Q42: 0 | R42: 0 | S42: 0 | T42: 0 | U42: 0 | V42: 0 | W42: 0
...

Sheet Sprint 2
A1: Project name: | C1: Xây dựng website đặt tour du lịch tích hợp hệ thống gợi ý dựa trên AI | F1: Muộn
A2: Module name: | C2: Sprint 2 | F2: Trước thời hạn
A3: Start date: | C3: 46127 | F3: Kết thúc đúng hạn
A4: End date: | C4: 46140
B6: SPRINT 2 REPORT
B7: No | C7: Thành viên | D7: Thực tế | E7: Ước tính
B8: 1 | C8: Phạm Văn Bảo | D8: =SUMIF($E$16:$F$87,"Bảo",$G$16:$G$87)+SUMIF($E$16:$F$87,"All team",$G$16:$G$87)/5+SUMIF($E$16:$F$87,"Bảo,Quân",$G$16:$G$87)/2+SUMIF($E$16:$F$87,"Bảo,Trung",$G$16:$G$87)/2 -> 34.1 | E8: =SUMIF($E$16:$F$90,"Bảo",$H$16:$H$90)+SUMIF($E$16:$F$90,"All team",$H$16:$H$90)/5+SUMIF($E$16:$F$90,"Bảo,Quân",$H$16:$H$90)/2+SUMIF($E$16:$F$90,"Bảo,Trung",$H$16:$H$90)/2 -> 32.2
B9: 2 | C9: Phạm Minh Quân | D9: =SUMIF($E$16:$F$87,"Quân",$G$16:$G$87)+SUMIF($E$16:$F$87,"All team",$G$16:$G$87)/5+SUMIF($E$16:$F$87,"Bảo,Quân",$G$16:$G$87)/2+SUMIF($E$16:$F$87,"Quân,Trung",$G$16:$G$87)/2 -> 46.6 | E9: =SUMIF($E$16:$F$87,"Quân",$H$16:$H$87)+SUMIF($E$16:$F$87,"All team",$H$16:$H$87)/5+SUMIF($E$16:$F$87,"Bảo,Quân",$H$16:$H$87)/2+SUMIF($E$16:$F$87,"Quân,Trung",$H$16:$H$87)/2 -> 49.2
B10: 3 | C10: Võ Hồ Thành Trung | D10: =SUMIF($E$16:$F$87,"Trung*",$G$16:$G$87)+SUMIF($E$16:$F$87,"All team",$G$16:$G$87)/5+SUMIF($E$16:$F$87,"Bảo,Trung",$G$16:$G$87)/2++SUMIF($E$16:$F$87,"Quân,Trung",$G$16:$G$87)/2 -> 32.1 | E10: =SUMIF($E$16:$F$87,"Trung*",$H$16:$H$87)+SUMIF($E$16:$F$87,"All team",$H$16:$H$87)/5+SUMIF($E$16:$F$87,"Bảo,Trung",$H$16:$H$87)/2++SUMIF($E$16:$F$87,"Quân,Trung",$H$16:$H$87)/2 -> 27.2
B11: 4 | C11: Lê Thanh Hà | D11: =SUMIF($E$16:$F$87,"Hà",$G$16:$G$87)+SUMIF($E$16:$F$87,"All team",$G$16:$G$87)/5 -> 48.6 | E11: =SUMIF($E$16:$F$87,"Hà",$H$16:$H$87)+SUMIF($E$16:$F$87,"All team",$H$16:$H$87)/5 -> 43.2
B12: 5 | C12: Nguyễn Thành Luân | D12: =SUMIF($E$16:$F$87,"Luân*",$G$16:$G$87)+SUMIF($E$16:$F$87,"All team",$G$16:$G$87)/5+SUMIF($E$16:$F$87,"Hà,Luân",$G$16:$G$87)/2 -> 32.6 | E12: =SUMIF($E$16:$F$87,"Luân*",$H$16:$H$87)+SUMIF($E$16:$F$87,"All team",$H$16:$H$87)/5+SUMIF($E$16:$F$87,"Hà,Luân",$H$16:$H$87)/2 -> 30.2
B13: Tổng | D13: =SUM(D8:D12) -> 194 | E13: =SUM(E8:E12) -> 182
A15: Sprint | B15: Compoment | C15: Task name | E15: Responsible Member | G15: Thực tế | H15: Ước tính | I15: 46115 | J15: 46116 | K15: 46117 | L15: 46118 | M15: 46119 | N15: 46120 | O15: 46121 | P15: 46122 | Q15: 46123 | R15: 46124 | S15: 46125 | T15: 46126 | U15: 46127 | V15: 46128
A16: Sprint 2 | B16: Họp kế hoạch Sprint | E16: All team | G16: 10 | H16: 10 | I16: 0 | J16: 0 | K16: 0 | L16: 0 | M16: 0 | N16: 0 | O16: 0 | P16: 0 | Q16: 0 | R16: 0 | S16: 0 | T16: 0 | U16: 0 | V16: 0
B17: Tạo Sprint Backlog 2 | E17: Bảo | G17: 5 | H17: 5 | I17: 5 | J17: 0 | K17: 0 | L17: 0 | M17: 0 | N17: 0 | O17: 0 | P17: 0 | Q17: 0 | R17: 0 | S17: 0 | T17: 0 | U17: 0 | V17: 0
B18: Tạo tài liệu kiểm thử cho Sprint | E18: Hà | G18: 5 | H18: 5 | I18: 5 | J18: 5 | K18: 0 | L18: 0 | M18: 0 | N18: 0 | O18: 0 | P18: 0 | Q18: 0 | R18: 0 | S18: 0 | T18: 0 | U18: 0 | V18: 0
B19: User interface design | C19: Giao diện quản lý thông tin cá nhân | E19: Hà | G19: 2 | H19: 2 | I19: 2 | J19: 2 | K19: 0 | L19: 0 | M19: 0 | N19: 0 | O19: 0 | P19: 0 | Q19: 0 | R19: 0 | S19: 0 | T19: 0 | U19: 0 | V19: 0
C20: Giao diện đánh giá | E20: Quân | G20: 2 | H20: 2 | I20: 2 | J20: 2 | K20: 0 | L20: 0 | M20: 0 | N20: 0 | O20: 0 | P20: 0 | Q20: 0 | R20: 0 | S20: 0 | T20: 0 | U20: 0 | V20: 0
C21: Giao diện quản lý tour | E21: Luân | G21: 3 | H21: 2 | I21: 2 | J21: 2 | K21: 0 | L21: 0 | M21: 0 | N21: 0 | O21: 0 | P21: 0 | Q21: 0 | R21: 0 | S21: 0 | T21: 0 | U21: 0 | V21: 0
K22: 1
C23: Giao diện quản lý dịch vụ | E23: Hà | G23: 2 | H23: 2 | I23: 2 | J23: 2 | K23: 0 | L23: 0 | M23: 0 | N23: 0 | O23: 0 | P23: 0 | Q23: 0 | R23: 0 | S23: 0 | T23: 0 | U23: 0 | V23: 0
C24: Giao diện quản lý đặt tour | E24: Trung | G24: 1 | H24: 2 | I24: 2 | J24: 1 | K24: 0 | L24: 0 | M24: 0 | N24: 0 | O24: 0 | P24: 0 | Q24: 0 | R24: 0 | S24: 0 | T24: 0 | U24: 0 | V24: 0
K25: 1
C26: Giao diện quản lý đánh giá | E26: Hà | G26: 2 | H26: 2 | I26: 2 | J26: 2 | K26: 0 | L26: 0 | M26: 0 | N26: 0 | O26: 0 | P26: 0 | Q26: 0 | R26: 0 | S26: 0 | T26: 0 | U26: 0 | V26: 0
C27: Giao diện xem hóa đơn | E27: Bảo | G27: 2 | H27: 2 | I27: 2 | J27: 2 | K27: 0 | L27: 0 | M27: 0 | N27: 0 | O27: 0 | P27: 0 | Q27: 0 | R27: 0 | S27: 0 | T27: 0 | U27: 0 | V27: 0
C28: Review all user interfaces of sprint 2 | E28: All team | G28: 4 | H28: 4 | I28: 4 | J28: 4 | K28: 0 | L28: 0 | M28: 0 | N28: 0 | O28: 0 | P28: 0 | Q28: 0 | R28: 0 | S28: 0 | T28: 0 | U28: 0 | V28: 0
B29: Design test case | C29: Thiết kế Quản lý thông tin cá nhân | E29: Hà | G29: 2 | H29: 2 | I29: 2 | J29: 2 | K29: 2 | L29: 0 | M29: 0 | N29: 0 | O29: 0 | P29: 0 | Q29: 0 | R29: 0 | S29: 0 | T29: 0 | U29: 0 | V29: 0
C30: Thiết kế Đánh giá | E30: Luân | G30: 2 | H30: 2 | I30: 2 | J30: 2 | K30: 2 | L30: 0 | M30: 0 | N30: 0 | O30: 0 | P30: 0 | Q30: 0 | R30: 0 | S30: 0 | T30: 0 | U30: 0 | V30: 0
C31: Thiết kế Quản lý tour | E31: Hà | G31: 2 | H31: 2 | I31: 2 | J31: 2 | K31: 2 | L31: 0 | M31: 0 | N31: 0 | O31: 0 | P31: 0 | Q31: 0 | R31: 0 | S31: 0 | T31: 0 | U31: 0 | V31: 0
C32: Thiết kế Quản lý dịch vụ | E32: Luân | G32: 3 | H32: 2 | I32: 2 | J32: 2 | K32: 2 | L32: 0 | M32: 0 | N32: 0 | O32: 0 | P32: 0 | Q32: 0 | R32: 0 | S32: 0 | T32: 0 | U32: 0 | V32: 0
L33: 1
C34: Thiết kế Quản lý đặt tour | E34: Hà | G34: 4 | H34: 2 | I34: 2 | J34: 2 | K34: 2 | L34: 0 | M34: 0 | N34: 0 | O34: 0 | P34: 0 | Q34: 0 | R34: 0 | S34: 0 | T34: 0 | U34: 0 | V34: 0
L35: 2 | M35: 0 | N35: 0 | O35: 0 | P35: 0 | Q35: 0 | R35: 0 | S35: 0 | T35: 0 | U35: 0 | V35: 0
C36: Thiết kế quản lý đánh giá | E36: Luân | G36: 2 | H36: 2 | I36: 2 | J36: 2 | K36: 2 | L36: 0 | M36: 0 | N36: 0 | O36: 0 | P36: 0 | Q36: 0 | R36: 0 | S36: 0 | T36: 0 | U36: 0 | V36: 0
C37: Thiết kế xem hóa đơn | E37: Hà | G37: 2 | H37: 2 | I37: 2 | J37: 2 | K37: 2 | L37: 2 | M37: 0 | N37: 0 | O37: 0 | P37: 0 | Q37: 0 | R37: 0 | S37: 0 | T37: 0 | U37: 0 | V37: 0
C38: Review all test case of Sprint 2 | E38: All team | G38: 7 | H38: 5 | I38: 5 | J38: 5 | K38: 5 | L38: 5 | M38: 0 | N38: 0 | O38: 0 | P38: 0 | Q38: 0 | R38: 0 | S38: 0 | T38: 0 | U38: 0 | V38: 0
M39: 2
B40: Coding | C40: Code back-end cho Quản lý thông tin cá nhân | E40: Hà | G40: 5 | H40: 2 | I40: 2 | J40: 2 | K40: 2 | L40: 2 | M40: 2 | N40: 2 | O40: 0 | P40: 0 | Q40: 0 | R40: 0 | S40: 0 | T40: 0 | U40: 0 | V40: 0
O41: 3
C42: Thiết kê front-end cho Quản lý thông tin cá nhân | E42: Hà | G42: 2 | H42: 2 | I42: 2 | J42: 2 | K42: 2 | L42: 2 | M42: 2 | N42: 2 | O42: 0 | P42: 0 | Q42: 0 | R42: 0 | S42: 0 | T42: 0 | U42: 0 | V42: 0
...

Sheet Sprint 3
A1: Project name: | C1: Xây dựng website đặt tour du lịch tích hợp hệ thống gợi ý dựa trên AI | F1: Muộn
A2: Module name: | C2: Sprint 3 | F2: Trước thời hạn
A3: Start date: | C3: 46141 | F3: Kết thúc đúng hạn
A4: End date: | C4: 46152
B6: SPRINT 3 REPORT
B7: No | C7: Thành viên | D7: Thực tế | E7: Ước tính
B8: 1 | C8: Phạm Văn Bảo | D8: =SUMIF($E$16:$F$79,"Bảo",$G$16:$G$79)+SUMIF($E$16:$F$79,"All team",$G$16:$G$79)/5+SUMIF($E$16:$F$79,"Bảo,Quân",$G$16:$G$79)/2+SUMIF($E$16:$F$79,"Bảo,Trung",$G$16:$G$79)/2+SUMIF($E$16:$F$79,"Bảo,Hà",$G$16:$G$79)/2 -> 65.6 | E8: =SUMIF($E$16:$F$79,"Bảo",$H$16:$H$79)+SUMIF($E$16:$F$79,"All team",$H$16:$H$79)/5+SUMIF($E$16:$F$79,"Bảo,Quân",$H$16:$H$79)/2+SUMIF($E$16:$F$79,"Bảo,Trung",$H$16:$H$79)/2+SUMIF($E$16:$F$79,"Bảo,Hà",$H$16:$H$79)/2 -> 49.6
B9: 2 | C9: Phạm Minh Quân | D9: =SUMIF($E$16:$F$79,"Quân",$G$16:$G$79)+SUMIF($E$16:$F$79,"All team",$G$16:$G$79)/5+SUMIF($E$16:$F$79,"Bảo,Quân",$G$16:$G$79)/2+SUMIF($E$16:$F$79,"Quân,Trung",$G$16:$G$79)/2 -> 39.6 | E9: =SUMIF($E$16:$F$79,"Quân",$H$16:$H$79)+SUMIF($E$16:$F$79,"All team",$H$16:$H$79)/5+SUMIF($E$16:$F$79,"Bảo,Quân",$H$16:$H$79)/2+SUMIF($E$16:$F$79,"Quân,Trung",$H$16:$H$79)/2 -> 42.6
B10: 3 | C10: Võ Hồ Thành Trung | D10: =SUMIF($E$16:$F$79,"Trung*",$G$16:$G$79)+SUMIF($E$16:$F$79,"All team",$G$16:$G$79)/5+SUMIF($E$16:$F$79,"Bảo,Trung",$G$16:$G$79)/2++SUMIF($E$16:$F$79,"Quân,Trung",$G$16:$G$79)/2 -> 14.6 | E10: =SUMIF($E$16:$F$79,"Trung*",$H$16:$H$79)+SUMIF($E$16:$F$79,"All team",$H$16:$H$79)/5+SUMIF($E$16:$F$79,"Bảo,Trung",$H$16:$H$79)/2++SUMIF($E$16:$F$79,"Quân,Trung",$H$16:$H$79)/2 -> 13.6
B11: 4 | C11: Lê Thanh Hà | D11: =SUMIF($E$16:$F$87,"Hà",$G$16:$G$87)+SUMIF($E$16:$F$87,"All team",$G$16:$G$87)/5+SUMIF($E$16:$F$87,"Bảo,Hà",$G$16:$G$87)/2 -> 41.1 | E11: =SUMIF($E$16:$F$87,"Hà",$H$16:$H$87)+SUMIF($E$16:$F$87,"All team",$H$16:$H$87)/5+SUMIF($E$16:$F$87,"Bảo,Hà",$H$16:$H$87)/2 -> 39.6
B12: 5 | C12: Nguyễn Thành Luân | D12: =SUMIF($E$16:$F$79,"Luân*",$G$16:$G$79)+SUMIF($E$16:$F$79,"All team",$G$16:$G$79)/5+SUMIF($E$16:$F$79,"Hà,Luân",$G$16:$G$79)/2 -> 30.6 | E12: =SUMIF($E$16:$F$79,"Luân",$H$16:$H$79)+SUMIF($E$16:$F$79,"ALL team",$H$16:$H$79)/5 -> 26.6
B13: Tổng | D13: =SUM(D8:D12) -> 191.5 | E13: =SUM(E8:E12) -> 172
A15: Sprint | B15: Compoment | C15: Task name | E15: Responsible Member | G15: Thực tế | H15: Ước tính | I15: 46129 | J15: 46130 | K15: 46131 | L15: 46132 | M15: 46133 | N15: 46134 | O15: 46135 | P15: 46136 | Q15: 46137 | R15: 46138 | S15: 46139 | T15: 46140 | U15: 46141 | V15: 46142 | W15: 46143 | X15: 46144 | Y15: 46145 | Z15: 46146 | AA15: 46147 | AB15: 46148 | AC15: 46149 | AD15: 46150 | AE15: 46151 | AF15: 46152 | AG15: 46153
A16: Sprint 3 | B16: Họp kế hoạch Sprint | E16: All team | G16: 10 | H16: 10 | I16: 0 | J16: 0 | K16: 0 | L16: 0 | M16: 0 | N16: 0 | O16: 0 | P16: 0 | Q16: 0 | R16: 0 | S16: 0 | T16: 0 | U16: 0 | V16: 0 | W16: 0 | X16: 0 | Y16: 0 | Z16: 0 | AA16: 0 | AB16: 0 | AC16: 0 | AD16: 0 | AE16: 0 | AF16: 0 | AG16: 0
B17: Tạo Sprint Backlog 3 | E17: Bảo | G17: 5 | H17: 5 | I17: 5 | J17: 0 | K17: 0 | L17: 0 | M17: 0 | N17: 0 | O17: 0 | P17: 0 | Q17: 0 | R17: 0 | S17: 0 | T17: 0 | U17: 0 | V17: 0 | W17: 0 | X17: 0 | Y17: 0 | Z17: 0 | AA17: 0 | AB17: 0 | AC17: 0 | AD17: 0 | AE17: 0 | AF17: 0 | AG17: 0
B18: Tạo tài liệu kiểm thử cho Sprint | E18: Hà | G18: 5 | H18: 5 | I18: 5 | J18: 0 | K18: 0 | L18: 0 | M18: 0 | N18: 0 | O18: 0 | P18: 0 | Q18: 0 | R18: 0 | S18: 0 | T18: 0 | U18: 0 | V18: 0 | W18: 0 | X18: 0 | Y18: 0 | Z18: 0 | AA18: 0 | AB18: 0 | AC18: 0 | AD18: 0 | AE18: 0 | AF18: 0 | AG18: 0
B19: User interface design | C19: Tìm kiếm | E19: Quân | G19: 1 | H19: 2 | I19: 2 | J19: 1 | K19: 0 | L19: 0 | M19: 0 | N19: 0 | O19: 0 | P19: 0 | Q19: 0 | R19: 0 | S19: 0 | T19: 0 | U19: 0 | V19: 0 | W19: 0 | X19: 0 | Y19: 0 | Z19: 0 | AA19: 0 | AB19: 0 | AC19: 0 | AD19: 0 | AE19: 0 | AF19: 0 | AG19: 0
K20: 1 | L20: 0 | M20: 0 | N20: 0 | O20: 0 | P20: 0 | Q20: 0 | R20: 0 | S20: 0 | T20: 0 | U20: 0 | V20: 0 | W20: 0 | X20: 0 | Y20: 0 | Z20: 0 | AA20: 0 | AB20: 0 | AC20: 0 | AD20: 0 | AE20: 0 | AF20: 0 | AG20: 0
C21: Quản lý tài khoản | E21: Luân | G21: 2 | H21: 2 | I21: 2 | J21: 2 | K21: 0 | L21: 0 | M21: 0 | N21: 0 | O21: 0 | P21: 0 | Q21: 0 | R21: 0 | S21: 0 | T21: 0 | U21: 0 | V21: 0 | W21: 0 | X21: 0 | Y21: 0 | Z21: 0 | AA21: 0 | AB21: 0 | AC21: 0 | AD21: 0 | AE21: 0 | AF21: 0 | AG21: 0
C22: Quản lý khuyến mãi | E22: Hà | G22: 2 | H22: 2 | I22: 2 | J22: 2 | K22: 0 | L22: 0 | M22: 0 | N22: 0 | O22: 0 | P22: 0 | Q22: 0 | R22: 0 | S22: 0 | T22: 0 | U22: 0 | V22: 0 | W22: 0 | X22: 0 | Y22: 0 | Z22: 0 | AA22: 0 | AB22: 0 | AC22: 0 | AD22: 0 | AE22: 0 | AF22: 0 | AG22: 0
C23: Báo cáo thống kê | E23: Trung | G23: 2 | H23: 2 | I23: 2 | J23: 2 | K23: 2 | L23: 0 | M23: 0 | N23: 0 | O23: 0 | P23: 0 | Q23: 0 | R23: 0 | S23: 0 | T23: 0 | U23: 0 | V23: 0 | W23: 0 | X23: 0 | Y23: 0 | Z23: 0 | AA23: 0 | AB23: 0 | AC23: 0 | AD23: 0 | AE23: 0 | AF23: 0 | AG23: 0
C24: Chatbot | E24: Bảo | G24: 1 | H24: 2 | I24: 2 | J24: 2 | K24: 1 | L24: 0 | M24: 0 | N24: 0 | O24: 0 | P24: 0 | Q24: 0 | R24: 0 | S24: 0 | T24: 0 | U24: 0 | V24: 0 | W24: 0 | X24: 0 | Y24: 0 | Z24: 0 | AA24: 0 | AB24: 0 | AC24: 0 | AD24: 0 | AE24: 0 | AF24: 0 | AG24: 0
L25: 1 | M25: 0 | N25: 0 | O25: 0 | P25: 0 | Q25: 0 | R25: 0 | S25: 0 | T25: 0 | U25: 0 | V25: 0 | W25: 0 | X25: 0 | Y25: 0 | Z25: 0 | AA25: 0 | AB25: 0 | AC25: 0 | AD25: 0 | AE25: 0 | AF25: 0 | AG25: 0
C26: Quản lý thanh toán | E26: Hà | G26: 2 | H26: 2 | I26: 2 | J26: 2 | K26: 2 | L26: 0 | M26: 0 | N26: 0 | O26: 0 | P26: 0 | Q26: 0 | R26: 0 | S26: 0 | T26: 0 | U26: 0 | V26: 0 | W26: 0 | X26: 0 | Y26: 0 | Z26: 0 | AA26: 0 | AB26: 0 | AC26: 0 | AD26: 0 | AE26: 0 | AF26: 0 | AG26: 0
C27: Review all user interfaces of sprint 3 | E27: All team | G27: 2 | H27: 2 | I27: 2 | J27: 2 | K27: 2 | L27: 0 | M27: 0 | N27: 0 | O27: 0 | P27: 0 | Q27: 0 | R27: 0 | S27: 0 | T27: 0 | U27: 0 | V27: 0 | W27: 0 | X27: 0 | Y27: 0 | Z27: 0 | AA27: 0 | AB27: 0 | AC27: 0 | AD27: 0 | AE27: 0 | AF27: 0 | AG27: 0
B28: Design test case | C28: Thiết kế Tìm kiếm | E28: Hà | G28: 1 | H28: 2 | I28: 2 | J28: 2 | K28: 2 | L28: 1 | M28: 0 | N28: 0 | O28: 0 | P28: 0 | Q28: 0 | R28: 0 | S28: 0 | T28: 0 | U28: 0 | V28: 0 | W28: 0 | X28: 0 | Y28: 0 | Z28: 0 | AA28: 0 | AB28: 0 | AC28: 0 | AD28: 0 | AE28: 0 | AF28: 0 | AG28: 0
M29: 1 | N29: 0 | O29: 0 | P29: 0 | Q29: 0 | R29: 0 | S29: 0 | T29: 0 | U29: 0 | V29: 0 | W29: 0 | X29: 0 | Y29: 0 | Z29: 0 | AA29: 0 | AB29: 0 | AC29: 0 | AD29: 0 | AE29: 0 | AF29: 0 | AG29: 0
C30: Thiết kế Quản lý tài khoản | E30: Luân | G30: 2 | H30: 2 | I30: 2 | J30: 2 | K30: 2 | L30: 2 | M30: 0 | N30: 0 | O30: 0 | P30: 0 | Q30: 0 | R30: 0 | S30: 0 | T30: 0 | U30: 0 | V30: 0 | W30: 0 | X30: 0 | Y30: 0 | Z30: 0 | AA30: 0 | AB30: 0 | AC30: 0 | AD30: 0 | AE30: 0 | AF30: 0 | AG30: 0
C31: Thiết kế Quản lý khuyến mãi | E31: Hà | G31: 2 | H31: 2 | I31: 2 | J31: 2 | K31: 2 | L31: 2 | M31: 2 | N31: 0 | O31: 0 | P31: 0 | Q31: 0 | R31: 0 | S31: 0 | T31: 0 | U31: 0 | V31: 0 | W31: 0 | X31: 0 | Y31: 0 | Z31: 0 | AA31: 0 | AB31: 0 | AC31: 0 | AD31: 0 | AE31: 0 | AF31: 0 | AG31: 0
C32: Thiết kế Báo cáo thống kê | E32: Luân | G32: 4 | H32: 2 | I32: 2 | J32: 2 | K32: 2 | L32: 2 | M32: 2 | N32: 0 | O32: 0 | P32: 0 | Q32: 0 | R32: 0 | S32: 0 | T32: 0 | U32: 0 | V32: 0 | W32: 0 | X32: 0 | Y32: 0 | Z32: 0 | AA32: 0 | AB32: 0 | AC32: 0 | AD32: 0 | AE32: 0 | AF32: 0 | AG32: 0
N33: 2 | O33: 0 | P33: 0 | Q33: 0 | R33: 0 | S33: 0 | T33: 0 | U33: 0 | V33: 0 | W33: 0 | X33: 0 | Y33: 0 | Z33: 0 | AA33: 0 | AB33: 0 | AC33: 0 | AD33: 0 | AE33: 0 | AF33: 0 | AG33: 0
C34: Thiết kế Chatbot | E34: Hà | G34: 2 | H34: 2 | I34: 2 | J34: 2 | K34: 2 | L34: 2 | M34: 2 | N34: 2 | O34: 0 | P34: 0 | Q34: 0 | R34: 0 | S34: 0 | T34: 0 | U34: 0 | V34: 0 | W34: 0 | X34: 0 | Y34: 0 | Z34: 0 | AA34: 0 | AB34: 0 | AC34: 0 | AD34: 0 | AE34: 0 | AF34: 0 | AG34: 0
C35: Thiết kế Quản lý thanh toán | E35: Luân | G35: 2 | H35: 2 | I35: 2 | J35: 2 | K35: 2 | L35: 2 | M35: 2 | N35: 2 | O35: 0 | P35: 0 | Q35: 0 | R35: 0 | S35: 0 | T35: 0 | U35: 0 | V35: 0 | W35: 0 | X35: 0 | Y35: 0 | Z35: 0 | AA35: 0 | AB35: 0 | AC35: 0 | AD35: 0 | AE35: 0 | AF35: 0 | AG35: 0
C36: Review all user interfaces of sprint 3 | E36: All team | G36: 3 | H36: 3 | I36: 3 | J36: 3 | K36: 3 | L36: 3 | M36: 3 | N36: 3 | O36: 0 | P36: 0 | Q36: 0 | R36: 0 | S36: 0 | T36: 0 | U36: 0 | V36: 0 | W36: 0 | X36: 0 | Y36: 0 | Z36: 0 | AA36: 0 | AB36: 0 | AC36: 0 | AD36: 0 | AE36: 0 | AF36: 0 | AG36: 0
B37: Coding | C37: Code back-end cho Tìm kiếm | E37: Quân | G37: 3 | H37: 3 | I37: 3 | J37: 3 | K37: 3 | L37: 3 | M37: 3 | N37: 3 | O37: 3 | P37: 3 | Q37: 0 | R37: 0 | S37: 0 | T37: 0 | U37: 0 | V37: 0 | W37: 0 | X37: 0 | Y37: 0 | Z37: 0 | AA37: 0 | AB37: 0 | AC37: 0 | AD37: 0 | AE37: 0 | AF37: 0 | AG37: 0
C38: Code front-end cho Tìm kiếm | E38: Quân | G38: 2 | H38: 2 | I38: 2 | J38: 2 | K38: 2 | L38: 2 | M38: 2 | N38: 2 | O38: 2 | P38: 0 | Q38: 0 | R38: 0 | S38: 0 | T38: 0 | U38: 0 | V38: 0 | W38: 0 | X38: 0 | Y38: 0 | Z38: 0 | AA38: 0 | AB38: 0 | AC38: 0 | AD38: 0 | AE38: 0 | AF38: 0 | AG38: 0
C39: Code back-end cho Quản lý tài khoản | E39: Quân | G39: 8 | H39: 8 | I39: 8 | J39: 8 | K39: 8 | L39: 8 | M39: 8 | N39: 8 | O39: 8 | P39: 8 | Q39: 0 | R39: 0 | S39: 0 | T39: 0 | U39: 0 | V39: 0 | W39: 0 | X39: 0 | Y39: 0 | Z39: 0 | AA39: 0 | AB39: 0 | AC39: 0 | AD39: 0 | AE39: 0 | AF39: 0 | AG39: 0
C40: Code front-end cho Quản lý tài khoản | E40: Bảo | G40: 5 | H40: 5 | I40: 5 | J40: 5 | K40: 5 | L40: 5 | M40: 5 | N40: 5 | O40: 5 | P40: 0 | Q40: 0 | R40: 0 | S40: 0 | T40: 0 | U40: 0 | V40: 0 | W40: 0 | X40: 0 | Y40: 0 | Z40: 0 | AA40: 0 | AB40: 0 | AC40: 0 | AD40: 0 | AE40: 0 | AF40: 0 | AG40: 0
C41: Code back-end cho Quản lý khuyến mãi | E41: Bảo | G41: 8 | H41: 8 | I41: 8 | J41: 8 | K41: 8 | L41: 8 | M41: 8 | N41: 8 | O41: 8 | P41: 8 | Q41: 8 | R41: 8 | S41: 0 | T41: 0 | U41: 0 | V41: 0 | W41: 0 | X41: 0 | Y41: 0 | Z41: 0 | AA41: 0 | AB41: 0 | AC41: 0 | AD41: 0 | AE41: 0 | AF41: 0 | AG41: 0
C42: Code front-end cho Quản lý khuyến mãi | E42: Hà | G42: 5 | H42: 5 | I42: 5 | J42: 5 | K42: 5 | L42: 5 | M42: 5 | N42: 5 | O42: 5 | P42: 5 | Q42: 0 | R42: 0 | S42: 0 | T42: 0 | U42: 0 | V42: 0 | W42: 0 | X42: 0 | Y42: 0 | Z42: 0 | AA42: 0 | AB42: 0 | AC42: 0 | AD42: 0 | AE42: 0 | AF42: 0 | AG42: 0
...

Sheet Total
A1: SPRINT BACKLOG REPORT
B2: Bảo | D2: Quân | F2: Trung | H2: Hà | J2: Luân
B3: Thực tế | C3: Ước tính | D3: Thực tế | E3: Ước tính | F3: Thực tế | G3: Ước tính | H3: Thực tế | I3: Ước tính | J3: Thực tế | K3: Ước tính
A4: Sprint 1 | B4: ='Sprint 1'!$D$8 -> 37.5 | C4: ='Sprint 1'!$E$8 -> 41.2 | D4: ='Sprint 1'!$D$9 -> 30.5 | E4: ='Sprint 1'!$E$9 -> 30.2 | F4: ='Sprint 1'!$D$10 -> 34.5 | G4: ='Sprint 1'!$E$10 -> 36.2 | H4: ='Sprint 1'!$D$11 -> 33.5 | I4: ='Sprint 1'!$E$11 -> 37.2 | J4: ='Sprint 1'!$D$12 -> 28 | K4: ='Sprint 1'!$E$12 -> 28.2
A5: Sprint 2 | B5: ='Sprint 2'!D8 -> 34.1 | C5: ='Sprint 2'!$E$8 -> 32.2 | D5: ='Sprint 2'!$D$9 -> 46.6 | E5: ='Sprint 2'!$E$9 -> 49.2 | F5: ='Sprint 2'!$D$10 -> 32.1 | G5: ='Sprint 2'!$E$10 -> 27.2 | H5: ='Sprint 2'!$D$11 -> 48.6 | I5: ='Sprint 2'!$E$11 -> 43.2 | J5: ='Sprint 2'!$D$12 -> 32.6 | K5: ='Sprint 2'!$E$12 -> 30.2
A6: Sprint 3 | B6: ='Sprint 3'!D8 -> 65.6 | C6: ='Sprint 3'!E8 -> 49.6 | D6: ='Sprint 3'!D9 -> 39.6 | E6: ='Sprint 3'!$E$9 -> 42.6 | F6: ='Sprint 3'!$D$10 -> 14.6 | G6: ='Sprint 3'!$E$10 -> 13.6 | H6: ='Sprint 3'!$D$11 -> 41.1 | I6: ='Sprint 3'!$E$11 -> 39.6 | J6: ='Sprint 3'!$D$12 -> 30.6 | K6: ='Sprint 3'!$E$12 -> 26.6
A7: Tổng | B7: =SUM(B4:B6) -> 137.2 | C7: =SUM(C4:C6) -> 123 | D7: =SUM(D4:D6) -> 116.7 | E7: =SUM(E4:E6) -> 122 | F7: =SUM(F4:F6) -> 81.2 | G7: =SUM(G4:G6) -> 77 | H7: =SUM(H4:H6) -> 123.2 | I7: =SUM(I4:I6) -> 120 | ... K7: =SUM(K4:K6) -> 85
E10: FINAL TOTAL
E11: Thực tế | F11: =SUMIF($B$3:$K$3,"Thực tế",$B$7:$K$7) -> 549.5
E12: Ước tính | F12: =SUMIF($B$3:$K$3,"Ước tính",$B$7:$K$7) -> 527
